Workbook

Sheet Instructivo
C1: INSTITUTO HONDUREÑO DE SEGURIDAD SOCIAL
C2: INSTRUCTIVO PARA EL LLENADO DE LA MATRIZ DE RIESGOS
B4: I. INTRODUCCIÓN
B5: La presente guía se ha elaborado para facilitar y orientar al personal de la Unidad de Riesgos, enlaces de riesgos operacionales ubicados en las diferentes dependencias del IHSS, y demás personal en la identificación, evaluación y registro de riesgos del IHSS, con base en los procesos y procedimientos institucionales, así como los que surgen en las diferentes operaciones, transacciones y actividades que se desarrollan.
B6: Se pretende describir los principales riesgos que pueden presentarse en los diferentes procesos y/o procedimientos operativos de cada uno de los regímenes del IHSS y áreas de la administración central.
B7: Cada Gerente, Subgerente o Jefe debe administrar los principales procesos y procedimientos operativos que se ejecutan en las áreas que dirigen, de manera periódica debe mantener comunicación cercana con el Departamento de Organizaciones y Métodos con el propósito de conocer el portafolio de procesos y procedimientos correspondientes.
B8: Es importante destacar que los procesos y procedimientos deben estar actualizados, es decir que considere los cambios tecnológicos, legales, normativos y otros factores internos o externos que pueden afectarlos.
B10: II. OBJETIVO
B11: Diseñar las diferentes consideraciones que faciliten a la Unidad de Gestión de Riesgos, diferentes áreas y enlaces de riesgos operacionales autorizados, la identificación, evaluación y medición de los diferentes riesgos operativos, tecnológicos y legales, con un llenado adecuado del formato de matriz de riesgos oficial; incluyendo la forma de documentar controles preventivos, detectivos y correctivos y la mecánica de cálculo automático del Valor del Riesgo Residual.
B13: III. CONCEPTOS BÁSICOS SOBRE RIESGOS Y GENERALIDADES DEL FORMATO DE LA MATRIZ DE RIESGOS DEL IHSS
B14: Se entiende por riesgo, la posibilidad de que un evento ocurra que tendría un impacto negativo en la consecución de los objetivos (de la persona, empresa o institución); y, por control, las políticas, normas, procedimientos, instructivos y otras acciones para prevenir, detectar o corregir riesgos.
B15: En el proceso de gestión de los riesgos, es necesaria la intervención de TODOS los empleados del IHSS que participan de las diferentes fases de los procesos, ya que conocen su funcionamiento y deben orientar el desarrollo de dicha gestión.
B16: La plantilla del formato de matriz de riesgos cuentas con diferentes columnas de información los cuales deben llenarse, por esta razón el personal de la Unidad de Gestión de Riesgos, enlaces de riesgos operacional u otro personal debe tener en cuenta las siguientes generalidades:
B18: 1. La plantilla consta de cuatro hojas:
C19: a) Instructivo (Instrucciones sobre el llenado de la matriz de riesgos)
C20: b) Matriz Consolidada (registro por riesgo).
C21: c) Otras tablas (Definiciones de controles por riesgo).
C22: d) Listas (tablas de respaldo para validaciones y listas desplegables).
B24: 2. Convenciones de captura de acuerdo al color de las columnas (leyenda):
C25: Celdas en color blanco: Ingreso manual.
C26: Celdas en color oro claro: Listas desplegables (valores predefinidos)
C27: Celdas en color verde claro: Cálculo automático, estas celdas no se pueden modificar.
C28: Celdas en color azul claro: Uso exclusivo para riesgos de tipo tecnológico.
B30: 3. En la Matriz Consolidada, el campo “Riesgo Residual” reproducirá exactamente la misma redacción del “Riesgo Inherente”, conforme a la pauta ya establecida en el Manual. El cálculo asociado se refleja únicamente en el campo “Valor del Riesgo Residual”.
B33: IV. INSUMOS O ENTRADAS:
B34: Los principales insumos para la gestión de riesgos son los objetivos institucionales vigentes, procesos y procedimientos, normativas aplicables, evidencias de operación de controles y registros de incidentes.
B36: V. DOCUMENTOS DE REFERENCIA:
C37: Manual de Gestión Integral de Riesgos del IHSS
C38: Reporte de eventos de riesgos
C39: Procedimiento de Monitoreo de Controles
B41: VI. DESCRIPCIÓN E INSTRUCCIONES PARA EL LLENADO DE LOS CAMPOS DE LA MATRIZ:
B42: Para facilitar el llenado del formato de matriz de riesgos se establecen diferentes instrucciones y pasos a seguir para aplicarse y facilitar la evaluación de los riesgos. La Matriz de Riesgos está compuesta por distintos campos de información, es importante señalar que, para el caso de las matrices de riesgos tecnológicos el formato de matrices de riesgos contara con 3 columnas adicionales a las que se describen en este apartado estas son: amenazas, vulnerabilidades y los activos de información. A continuación, se describe la información correspondiente a cada columna:
B44: No.: | C44: Todos los riesgos deben enumerarse desde 1 hasta la cantidad de riesgos que identifique cada uno de los Regímenes, áreas administrativas a nivel central, región norte y otras regiones donde el IHSS presenta servicios. (ejemplo, 1,2,3,4,5, 6...1000 etc.).
B45: Código del Riesgo: | C45: Llenado automático. Se codifica siguiendo la convención institucional por tipo de riesgo, área/régimen y número secuencial. Ejemplo: RO-GTIC-01, RO-GTIC-02
B46: Tipo de Riesgo: | C46: Selección manual. Seleccionar el tipo de riesgo: Operativo, Legal o Tecnológico.
B47: Proceso / Procedimiento: | C47: Escribir el proceso o procedimiento que se ve afectado por el riesgo que se evalúa. Se debe considerar contar con las políticas, procesos y procedimientos aplicables al área actualizados.
B48: Objetivos estratégicos: | C48: De acuerdo al PEI se debe Especificar el Objetivo estratégico institucional que se ve afectado por el riesgo identificado.
B49: Riesgo Inherente: | C49: Se escribe el nombre del riesgo. Estos se identificarán y evaluarán de sus principales procesos/ procedimientos con respecto a: • Aquellos relacionados a operaciones no autorizadas, extravíos de bienes, uso indebido de facultades y poderes, operaciones no reveladas entre otras. • Errores o fallas relacionadas a los servicios, modelos, otorgamiento de beneficios a derecho habientes, pensionados, jubilados, así como errores en; contratos y en el registro de datos u operaciones. • Errores contables, errores en procesos, información o datos incompletos o inexistentes. Se escribe el nombre del riesgo. Estos se identificarán y evaluarán de sus principales procesos/ procedimientos con respecto a: • Aquellos relacionados a operaciones no autorizadas, extravíos de bienes, uso indebido de facultades y poderes, operaciones no reveladas entre otras. • Errores o fallas relacionadas a los servicios, modelos, otorgamiento de beneficios a derecho habientes, pensionados, jubilados, así como errores en; contratos y en el registro de datos u operaciones. • Errores contables, errores en procesos, información o datos incompletos o inexistentes • Incumplimiento de plazos o responsabilidades regulatorias, normativas, contractuales o legales. • Debilidades en la Seguridad de los Sistemas de Información de los regímenes. • Daños o debilidades en la protección de loa activos físicos de los regímenes y áreas de la administración central. • Registros incorrectos en operaciones de los patronos, derechohabientes y los proveedores. • Fallas en; hardware, en software, medios de almacenamiento, telecomunicaciones y energía. • Divulgación de información, practicas improcedentes, servicios defectuosos. • Mantenimiento oportuno para reanudar las interrupciones provocadas respecto al funcionamiento de sistemas, hardware que permitan la continuidad de los servicios prestados a los derechohabientes en los diferentes regímenes. • Probables Incumplimiento con los elementos del control interno institucional y normativa de la CNBS, así como de otras leyes y reglamentación aplicables. • Debilidades o deficiencias en los principales procesos de las áreas con mayor exposición al riesgo • Otros Riesgos Operacionales que afecten los objetivos estratégicos de los regímenes y áreas de la administración Central del IHSS.
C50: En materia tecnológica aquellos riesgos relacionados a las posibilidades de escenarios relacionados a: • Vulneración de los sistemas de información, ataques informáticos o ciberataques, robo de información, uso de claves de accesos y niveles de autorización de manera inadecuada. • Códigos dañinos, errores humanos, denegación de servicios, interrupción de servicios, intrusiones externas, acceso no autorizado a la información, modificación y borrado de la información, incumplimientos a políticas de seguridad entre otros escenarios de riesgos posibles.
C51: En materia Legal lo riesgos relacionados a escenarios respecto a: • Litigios con proveedores, demandas de tipo laboral, otros escenarios de demandas.
...

Sheet Matriz Consolidada
A1: No. | B1: Código de Riesgo | C1: Área | D1: Área Consolidada | E1: Tipo de Riesgo | F1: Procedimiento | G1: Objetivo(s) Estratégico(s) | H1: Riesgo Inherente | I1: Evaluación | J1: Frecuencia | K1: Impacto | L1: Valor del Riesgo Inherente | M1: Nivel de Riesgo Inherente | N1: Responsable o dueño del riesgo | O1: Régimen afectado | P1: Transversalidad o Interrelación con otros Riesgos | Q1: Amenazas (Solo para riesgos de GTIC) | R1: Vulnerabilidades (Solo para riesgos de GTIC) | S1: Activos de Información (Solo para riesgos de GTIC) | T1: Descripción de Control(es) Preventivo(s) | U1: Escala de efectividad de control(es) preventivo(s) | V1: Nivel de efectividad de control(es) preventivo(s) | W1: % efectividad de control(es) preventivo(s) | X1: Descripción de Control(es) Detectivo(s) | Y1: Escala de efectividad de control(es) detectivo(s) | Z1: Nivel de efectividad de control(es) detectivo(s) | AA1: % efectividad de control detectivo | AB1: Descripción de Control(es) Correctivo(s) | AC1: Escala de efectividad de control(es) correctivo(s) | AD1: Nivel de efectividad de control(es) correctivo(s) | AE1: % efectividad de control correctivo | AF1: Nivel de Automatización de los Controles | AG1: Efectividad Total Ponderada de los Controles | AH1: Riesgo Residual | AI1: Frecuencia Residual | AJ1: Impacto Residual | AK1: Valor del Riesgo Residual | AL1: Nivel del Riesgo Residual | AM1: Respuesta al riesgo | AN1: Plan de Mitigación/Acciones Correctivas | AO1: No. Acciones de Mitigación | AP1: Actividades | AQ1: Cantidad de Actividades | AR1: Monitoreo/ Seguimiento | AS1: Responsables | AT1: Fecha inicio | AU1: Fecha final | AV1: Recursos | AW1: Presupuesto | AX1: Frecuencia Residual (AUX) | AY1: Impacto Residual (AUX) | AZ1: Suma Residual redondeada (AUX) | BA1: F_base (AUX) | BB1: I_base (AUX) | BC1: Tope F (AUX) | BD1: Tope I (AUX) | BE1: Capacidad F (AUX) | BF1: Capacidad I (AUX) | BG1: Resto (AUX) | BH1: Prefiere I (AUX) | BI1: Inc_I (AUX) | BJ1: Inc_F (AUX) | BK1: Valor del Riesgo Residual (AUX) | BL1: Verificación | BM1: VRR 2 | BN1: Verificar VRR 2 | BO1: Verificar Frec | BP1: Verificar Impact | BQ1: VRI-VRR | BR1: Señales de Alerta | BS1: Estado del Riesgo | BT1: Estado del Control Preventivo | BU1: Evaluación de la Efectividad del Control Preventivo | BV1: Evidencia(s) del Control Preventivo | BW1: Estado del Control Detectivo | BX1: Evaluación de la Efectividad del Control Detectivo | BY1: Evidencia(s) del Control Detectivo | BZ1: Estado del Control Correctivo | CA1: Evaluación de la Efectividad del Control Correctivo | CB1: Evidencia(s) del Control Correctivo | CC1: Observaciones del Área | CD1: Observaciones UGR
A2: 1 | B2: ROTR-AFIL-1 | C2: Afiliacion | E2: Otros Riesgos | F2: Afiliacion | H2: Creación y activación de registros en el sistema correspondientes a identidades falsas, suplantadas o personas que no cumplen criterios normativos, contractuales o internos para su afiliacion. | I2: Descripción: Posibilidad de que el IHSS registre o afilie personas naturales o jurídicas inexistentes, suplantadas o que no cumplen los requisitos de elegibilidad establecidos, debido a deficiencias en los procesos de verificación de identidad, validación documental o controles de admisión. Causas: Ausencia de validación biométrica o verificación en fuentes oficiales, procesos manuales sin doble validación, colusión interna, documentación falsificada no detectada. Efecto: Pérdidas económicas por fraude / Afectación de imagen por vinculación con identidades ficticias / | J2: 3 | K2: 5 | L2: =IF((Matriz_Riesgos[[#This Row],[Frecuencia]]+Matriz_Riesgos[[#This Row],[Impacto]]-1)=-1,"",Matriz_Riesgos[[#This Row],[Frecuencia]]+Matriz_Riesgos[[#This Row],[Impacto]]-1) -> 7 | M2: =IFERROR(VLOOKUP(Matriz_Riesgos[[#This Row],[Valor del Riesgo Inherente]],t_nivel_riesgo[],2,FALSE), "") -> Riesgo Alto | N2: Control patronal/Planilla preelaborada/Afiliacion | O2: Todos | P2: Fraude, LAFT, Operativo, incumplimiento regulatorio | T2: 1.- Verificacion de identidad del afiliado y el patrono mediante consulta a bases oficiales gubernamentales y registros institucionales para confirmar autenticidad, vigencia y consistencia de la informacion. 2.- Validacion biometrica, firma electronica o mecanismos de autenticacion digital, para confirmar correspondencia entre el solicitante y la identidad registrada. 3. Parametrización obligatoria de requisitos de elegibilidad, es decir configuracion de reglas automaticas en el sistema que impidan registrar afiliaciones que no cumplan con los requisitos normativos, documentales, salariales o de relacion laboral. El sistema debe bloquear registros incompletos, inconsistentes o fuera de parametros. 4. Segregación de funciones entre registro y aprobación, es decir: Separacion de responsabilidades entre captura, validacion y aprobacion de afiliaciones. El suistema debe impedir autoaprobaciones y mantiene trazabilidad de usuarios, cambios y autorizaciones | U2: Alta Efectividad | V2: =IFERROR(VLOOKUP(Matriz_Riesgos[[#This Row],[Escala de efectividad de control(es) preventivo(s)]],t_efectividad[],2,FALSE),"") -> 5 | W2: =IFERROR(VLOOKUP(Matriz_Riesgos[[#This Row],[Escala de efectividad de control(es) preventivo(s)]],t_efectividad[],3,FALSE),"") -> 0.9 | X2: 1. Monitoreo de afiliaciones inusuales. Es decir, generacion periodica de reportes para identificar patrones atipicos: multiples afiliaciones vinculadas a un mismo patrono, altas masivas, salarios inconsistentes o duplicidad documental. 2. Muestreo periodico de afiliaciones aprobadas para validacion documental, elegibilidad y cumplimiento de procedimientos. 3. Alertas automaticas por inconsistencias: Parametrizacion de alertas para detectar documentos duplicados, identidades repetidas, patronos inactivos o afiliaciones fuera de rango salarial permitido. | Y2: Alta Efectividad | Z2: =IFERROR(VLOOKUP(Matriz_Riesgos[[#This Row],[Escala de efectividad de control(es) detectivo(s)]],t_efectividad[],2,FALSE),"") -> 5 | AA2: =IFERROR(VLOOKUP(Matriz_Riesgos[[#This Row],[Escala de efectividad de control(es) detectivo(s)]],t_efectividad[],3,FALSE),"") -> 0.9 | AB2: 1. Inhabilitacion temporal de afiliaciones detectadas con inconsistencias hasta completar validacion. 2. Investigación interna y escalamiento. Remision de casos sospechosos a Auditoria Interna o instancia disciplinaria correspondiente. 3. Depuracion periodica de registros. revision y saneamiento de afiliaciones duplicadas, inactivas o irregulares detectadas en controles posteriores. | AC2: Alta Efectividad | AD2: =IFERROR(VLOOKUP(Matriz_Riesgos[[#This Row],[Escala de efectividad de control(es) correctivo(s)]],t_efectividad[],2,FALSE),"") -> 5 | AE2: =IFERROR(VLOOKUP(Matriz_Riesgos[[#This Row],[Escala de efectividad de control(es) correctivo(s)]],t_efectividad[],3,FALSE),"") -> 0.9 | AF2: Semiautomatizado | AG2: =IF(AND(T2="",X2="",AB2=""),"",('Otras Tablas'!$B$3*IF(W2="",0,W2)+'Otras Tablas'!$B$4*IF(AA2="",0,AA2)+'Otras Tablas'!$B$5*IF(AE2="",0,AE2))) | AH2: =IF(Matriz_Riesgos[[#This Row],[Riesgo Inherente]]="","",Matriz_Riesgos[[#This Row],[Riesgo Inherente]]) -> Creación y activación de registros en el sistema correspondientes a identidades falsas, suplantadas o personas que no cumplen criterios normativos, contractuales o internos para su afiliacion. | AI2: =IFERROR(IF(OR(Matriz_Riesgos[[#This Row],[Frecuencia]]="",Matriz_Riesgos[[#This Row],[Impacto]]="",Matriz_Riesgos[[#This Row],[Valor del Riesgo Inherente]]="",Matriz_Riesgos[[#This Row],[Valor del Riesgo Residual]]=""),"",IF(Matriz_Riesgos[[#This Row],[Valor del Riesgo Inherente]]=Matriz_Riesgos[[#This Row],[Valor del Riesgo Residual]],Matriz_Riesgos[[#This Row],[Frecuencia]],MIN(Matriz_Riesgos[[#This Row],[Tope F (AUX)]], Matriz_Riesgos[[#This Row],[F_base (AUX)]]+Matriz_Riesgos[[#This Row],[Inc_F (AUX)]]))),"") -> 1 | AJ2: =IFERROR(IF(OR(Matriz_Riesgos[[#This Row],[Frecuencia]]="",Matriz_Riesgos[[#This Row],[Impacto]]="",Matriz_Riesgos[[#This Row],[Valor del Riesgo Inherente]]="",Matriz_Riesgos[[#This Row],[Valor del Riesgo Residual]]=""),"",IF(Matriz_Riesgos[[#This Row],[Valor del Riesgo Inherente]]=Matriz_Riesgos[[#This Row],[Valor del Riesgo Residual]],Matriz_Riesgos[[#This Row],[Impacto]],MIN(Matriz_Riesgos[[#This Row],[Tope I (AUX)]], Matriz_Riesgos[[#This Row],[I_base (AUX)]]+Matriz_Riesgos[[#This Row],[Inc_I (AUX)]]))),"") -> 1 | AK2: =IFERROR(ROUND(MAX(1,Matriz_Riesgos[[#This Row],[Valor del Riesgo Inherente]]*(1 - Matriz_Riesgos[[#This Row],[Efectividad Total Ponderada de los Controles]])),0), "") -> 1 | AL2: =IFERROR(VLOOKUP(Matriz_Riesgos[[#This Row],[Valor del Riesgo Residual]],t_nivel_riesgo[],2,FALSE),"") -> Riesgo no significativo | AM2: Evitar | AN2: 1. Fortalecer validaciones automaticas de elegibilidad 2. Implementar controles de segregacion de funciones 3. Mejorar mecanismos de verificacion documental 4. Fortalecer monitoreo de afiliaciones inusuales 5. Realizar depuracion periodica de registros 6. Formalizar procedimientos de excepciones 7. Reforzar trazabilidad y auditoria 8. Capacitar al personal involucrado | AO2: 8 | AP2: 1.1 Parametrizar validaciones obligatorias 1.2. Incorporar bloqueos automaticos por inconsistencias 1.3. Validar duplicidad documental e identidad 2.1 Revisar perfiles de usuario 2.2 Eliminar permisos incompatibles 2.3 Configurar restricciones de autoaprobacion 2.4 Actualizar matrices de accesos 3.1 Estandarizar check lis documental 3.2 Capacitar al personal sobre documentos falsificados y señales de alerta 4.1 Diseñar reportes automatizados 4.2 identificar patrones atipicos 4.3 Realizar revisiones periodicas 5.1 Revisar afiliaciones duplicadas o inconsistentes 5.2 Confirmar vigencia de patronos 5.3 Corregir registros observados 6.1 Definir criterios de excepcion 6.2 Establecer niveles de autorizacion 6.3 Documentar y monitorear excepciones aprobadas 7.1 Activar bitacoras completas 7.2 Conservart historial de cambios y aprobaciones 8.1 Capacitaciones sobre LAFT, Señales de Alerta, etica y responsabilidad es de Control Interno | AQ2: 21 | AR2: 1. Revision mensual de afiliaciones aprobadas por excepcion 2. Revision mensual de Logs y Bitacoras 3. Muestreo trimestral de expedientes de afiliacion 4. Evaluacion anual de efectividad de controles | AS2: 1. Afiliacion / TI 2. Afiliacion / TI/ RRHH 3. Afiliacion / Legal / Cumplimiento 4. Cumplimiento /Auditoria / TI 5. Afiliacion / Auditoria 6. Cumplimiento / Afiliacion 7. TI / Auditoria 8. Cumplimiento / RRHH | AX2: =IFERROR((1-Matriz_Riesgos[[#This Row],[Efectividad Total Ponderada de los Controles]])*Matriz_Riesgos[[#This Row],[Frecuencia]],"") -> 0.3 | AY2: =IFERROR((1-Matriz_Riesgos[[#This Row],[Efectividad Total Ponderada de los Controles]])*Matriz_Riesgos[[#This Row],[Impacto]],"") -> 0.5 | AZ2: =IFERROR(Matriz_Riesgos[[#This Row],[Valor del Riesgo Residual]] + 1, "") -> 2 | BA2: =IFERROR(MAX(1, ROUNDDOWN(Matriz_Riesgos[[#This Row],[Frecuencia Residual (AUX)]],0)),"") -> 1 | BB2: =IFERROR(MAX(1, ROUNDDOWN(Matriz_Riesgos[[#This Row],[Impacto Residual (AUX)]],0)),"") -> 1 | BC2: =IF(Matriz_Riesgos[[#This Row],[Frecuencia]]="","",Matriz_Riesgos[[#This Row],[Frecuencia]]) -> 3 | BD2: =IF(Matriz_Riesgos[[#This Row],[Impacto]]="","",Matriz_Riesgos[[#This Row],[Impacto]]) -> 5 | BE2: =IF(OR(Matriz_Riesgos[[#This Row],[Tope F (AUX)]]="",Matriz_Riesgos[[#This Row],[F_base (AUX)]]=""),"",MAX(0,Matriz_Riesgos[[#This Row],[Tope F (AUX)]]-Matriz_Riesgos[[#This Row],[F_base (AUX)]])) -> 2 | BF2: =IF(OR(Matriz_Riesgos[[#This Row],[Tope I (AUX)]]="",Matriz_Riesgos[[#This Row],[I_base (AUX)]]=""),"",MAX(0,Matriz_Riesgos[[#This Row],[Tope I (AUX)]]-Matriz_Riesgos[[#This Row],[I_base (AUX)]])) -> 4 | BG2: =IF(OR(Matriz_Riesgos[[#This Row],[Suma Residual redondeada (AUX)]]="",Matriz_Riesgos[[#This Row],[F_base (AUX)]]="",Matriz_Riesgos[[#This Row],[I_base (AUX)]]=""),"",MAX(0,Matriz_Riesgos[[#This Row],[Suma Residual redondeada (AUX)]]-(Matriz_Riesgos[[#This Row],[F_base (AUX)]]+Matriz_Riesgos[[#This Row],[I_base (AUX)]]))) -> 0 | BH2: =IF(OR(Matriz_Riesgos[[#This Row],[Impacto Residual (AUX)]]="",Matriz_Riesgos[[#This Row],[Frecuencia Residual (AUX)]]=""),"",IF(MOD(Matriz_Riesgos[[#This Row],[Impacto Residual (AUX)]],1) > MOD(Matriz_Riesgos[[#This Row],[Frecuencia Residual (AUX)]],1),1,IF(MOD(Matriz_Riesgos[[#This Row],[Impacto Residual (AUX)]],1) = MOD(Matriz_Riesgos[[#This Row],[Frecuencia Residual (AUX)]],1),1,0))) -> 1 | BI2: =IF(OR(Matriz_Riesgos[[#This Row],[Resto (AUX)]]="",Matriz_Riesgos[[#This Row],[Capacidad I (AUX)]]="",Matriz_Riesgos[[#This Row],[Capacidad F (AUX)]]=""),"",IF(Matriz_Riesgos[[#This Row],[Resto (AUX)]]=0, 0,IF(Matriz_Riesgos[[#This Row],[Resto (AUX)]]=1,MIN(Matriz_Riesgos[[#This Row],[Capacidad I (AUX)]], IF(OR(Matriz_Riesgos[[#This Row],[Prefiere I (AUX)]]=1,Matriz_Riesgos[[#This Row],[Capacidad F (AUX)]]=0),1,0)),MIN(Matriz_Riesgos[[#This Row],[Capacidad I (AUX)]],IF(Matriz_Riesgos[[#This Row],[Prefiere I (AUX)]]=1,1 + IF(Matriz_Riesgos[[#This Row],[Capacidad F (AUX)]]>0,0,1),IF(Matriz_Riesgos[[#This Row],[Capacidad F (AUX)]]>0,1,2)))))) -> 0 | BJ2: =IF(OR(Matriz_Riesgos[[#This Row],[Resto (AUX)]]="",Matriz_Riesgos[[#This Row],[Capacidad F (AUX)]]="",Matriz_Riesgos[[#This Row],[Inc_I (AUX)]]=""),"",MIN(Matriz_Riesgos[[#This Row],[Capacidad F (AUX)]], MAX(0,Matriz_Riesgos[[#This Row],[Resto (AUX)]]-Matriz_Riesgos[[#This Row],[Inc_I (AUX)]]))) -> 0 | BK2: =IFERROR(MAX(ROUND(Matriz_Riesgos[[#This Row],[Frecuencia Residual (AUX)]]+Matriz_Riesgos[[#This Row],[Impacto Residual (AUX)]]-1+Matriz_Riesgos[[#This Row],[Efectividad Total Ponderada de los Controles]],0),1),"") -> 1 | BL2: =IFERROR(Matriz_Riesgos[[#This Row],[Valor del Riesgo Residual]]-Matriz_Riesgos[[#This Row],[Valor del Riesgo Residual (AUX)]],"") -> 0 | BM2: =IFERROR(Matriz_Riesgos[[#This Row],[Frecuencia Residual]]+Matriz_Riesgos[[#This Row],[Impacto Residual]]-1,"") -> 1 | BN2: =IFERROR(Matriz_Riesgos[[#This Row],[Valor del Riesgo Residual]]-Matriz_Riesgos[[#This Row],[VRR 2]],"") -> 0 | BO2: =IFERROR(Matriz_Riesgos[[#This Row],[Frecuencia]]-Matriz_Riesgos[[#This Row],[Frecuencia Residual]],"") -> 2 | BP2: =IFERROR(Matriz_Riesgos[[#This Row],[Impacto]]-Matriz_Riesgos[[#This Row],[Impacto Residual]],"") -> 4 | BQ2: =IFERROR(Matriz_Riesgos[[#This Row],[Valor del Riesgo Inherente]]-Matriz_Riesgos[[#This Row],[Valor del Riesgo Residual]],"") -> 6 | BR2: 1. Afiliaciones masivas atipicas 2. Patronos sin actividad verificable 3. Duplicidad documental 4. Excepciones recurrentes 5. Coincidencias de datos entre afiliados 6. Autoaprobaciones o intervencion repetitiva de funcionarios
A3: 2 | B3: ROTR-AFIL-2 | C3: Afiliacion | E3: Otros Riesgos | F3: Afiliacion | H3: Emisión de autorización o prestación efectiva de un servicio de salud a una persona que, no figura como afiliado al sistema o tiene afiliacion suspendida | I3: Descripción: Posibilidad de que el IHSS autorice y/o preste servicios médicos a personas que no se encuentren afiliadas, que hayan perdido su condición de afiliación o que no cumplan los requisitos legales y contractuales para acceder a los servicios, debido a fallas en los controles de validación de derechos, Causas: Sistemas desactualizados o sin integración, errores manuales del personal de admisiones, suplantación de identidad, falta de capacitación del personal, Parametrización incorrecta en el sistema de admisiones. Efecto: Pago de servicios no recuperables, investigaciones administrativas, redes organizadas para uso indebido de servicios | J3: 4 | K3: 4 | L3: =IF((Matriz_Riesgos[[#This Row],[Frecuencia]]+Matriz_Riesgos[[#This Row],[Impacto]]-1)=-1,"",Matriz_Riesgos[[#This Row],[Frecuencia]]+Matriz_Riesgos[[#This Row],[Impacto]]-1) -> 7 | M3: =IFERROR(VLOOKUP(Matriz_Riesgos[[#This Row],[Valor del Riesgo Inherente]],t_nivel_riesgo[],2,FALSE), "") -> Riesgo Alto | N3: Control patronal/Planilla preelaborada | O3: EM | P3: Fraude, riesgo operativo y financiero | T3: 1.- Validación automática y obligatoria del estado de afiliación previo a la emisión de autorizaciones y prestación de servicios. 2.- Integración entre los sistemas de afiliación, recaudación y atención médica para garantizar información actualizada en tiempo real. 3.- Restricción de acceso al sistema para impedir la generación manual de autorizaciones sin validación previa. 4.- Implementación de perfiles y segregación de funciones para el personal autorizado. 5.- Capacitación periódica al personal administrativo y asistencial sobre procedimientos de verificación de afiliación. 6.- Establecimiento de políticas y procedimientos formales para validación de derechos y cobertura. 7.- Uso de mecanismos de autenticación del afiliado mediante documento de identidad y validación biométrica cuando aplique. | U3: Alta Efectividad | V3: =IFERROR(VLOOKUP(Matriz_Riesgos[[#This Row],[Escala de efectividad de control(es) preventivo(s)]],t_efectividad[],2,FALSE),"") -> 5 | W3: =IFERROR(VLOOKUP(Matriz_Riesgos[[#This Row],[Escala de efectividad de control(es) preventivo(s)]],t_efectividad[],3,FALSE),"") -> 0.9 | X3: 1. Generación de reportes periódicos de autorizaciones emitidas a afiliados suspendidos o inexistentes. 2.- Conciliaciones mensuales entre base de afiliados activos y servicios prestados. 3.- Monitoreo de excepciones y alertas automáticas sobre inconsistencias en afiliación. 4.- Auditorías internas sobre expedientes médicos y autorizaciones emitidas. 5.- Revisión aleatoria de atenciones médicas otorgadas en periodos críticos o fuera de parámetros normales. 6.- Seguimiento de usuarios con alto volumen de anulaciones o modificaciones de autorizaciones. | Y3: Alta Efectividad | Z3: =IFERROR(VLOOKUP(Matriz_Riesgos[[#This Row],[Escala de efectividad de control(es) detectivo(s)]],t_efectividad[],2,FALSE),"") -> 5 | AA3: =IFERROR(VLOOKUP(Matriz_Riesgos[[#This Row],[Escala de efectividad de control(es) detectivo(s)]],t_efectividad[],3,FALSE),"") -> 0.9 | AB3: 1. Suspensión inmediata de accesos o permisos a usuarios involucrados en irregularidades. 2. Anulación de autorizaciones emitidas indebidamente cuando proceda. 3. Recuperación administrativa o legal de valores pagados indebidamente. 4. Investigación interna de casos detectados y documentación de hallazgos. 5. Aplicación de medidas disciplinarias conforme normativa institucional. 6. Actualización de procedimientos y controles derivados de incidentes identificados. | AC3: Alta Efectividad | AD3: =IFERROR(VLOOKUP(Matriz_Riesgos[[#This Row],[Escala de efectividad de control(es) correctivo(s)]],t_efectividad[],2,FALSE),"") -> 5 | AE3: =IFERROR(VLOOKUP(Matriz_Riesgos[[#This Row],[Escala de efectividad de control(es) correctivo(s)]],t_efectividad[],3,FALSE),"") -> 0.9 | AF3: Semiautomatizado | AG3: =IF(AND(T3="",X3="",AB3=""),"",('Otras Tablas'!$B$3*IF(W3="",0,W3)+'Otras Tablas'!$B$4*IF(AA3="",0,AA3)+'Otras Tablas'!$B$5*IF(AE3="",0,AE3))) | AH3: =IF(Matriz_Riesgos[[#This Row],[Riesgo Inherente]]="","",Matriz_Riesgos[[#This Row],[Riesgo Inherente]]) -> Emisión de autorización o prestación efectiva de un servicio de salud a una persona que, no figura como afiliado al sistema o tiene afiliacion suspendida | AI3: =IFERROR(IF(OR(Matriz_Riesgos[[#This Row],[Frecuencia]]="",Matriz_Riesgos[[#This Row],[Impacto]]="",Matriz_Riesgos[[#This Row],[Valor del Riesgo Inherente]]="",Matriz_Riesgos[[#This Row],[Valor del Riesgo Residual]]=""),"",IF(Matriz_Riesgos[[#This Row],[Valor del Riesgo Inherente]]=Matriz_Riesgos[[#This Row],[Valor del Riesgo Residual]],Matriz_Riesgos[[#This Row],[Frecuencia]],MIN(Matriz_Riesgos[[#This Row],[Tope F (AUX)]], Matriz_Riesgos[[#This Row],[F_base (AUX)]]+Matriz_Riesgos[[#This Row],[Inc_F (AUX)]]))),"") -> 1 | AJ3: =IFERROR(IF(OR(Matriz_Riesgos[[#This Row],[Frecuencia]]="",Matriz_Riesgos[[#This Row],[Impacto]]="",Matriz_Riesgos[[#This Row],[Valor del Riesgo Inherente]]="",Matriz_Riesgos[[#This Row],[Valor del Riesgo Residual]]=""),"",IF(Matriz_Riesgos[[#This Row],[Valor del Riesgo Inherente]]=Matriz_Riesgos[[#This Row],[Valor del Riesgo Residual]],Matriz_Riesgos[[#This Row],[Impacto]],MIN(Matriz_Riesgos[[#This Row],[Tope I (AUX)]], Matriz_Riesgos[[#This Row],[I_base (AUX)]]+Matriz_Riesgos[[#This Row],[Inc_I (AUX)]]))),"") -> 1 | AK3: =IFERROR(ROUND(MAX(1,Matriz_Riesgos[[#This Row],[Valor del Riesgo Inherente]]*(1 - Matriz_Riesgos[[#This Row],[Efectividad Total Ponderada de los Controles]])),0), "") -> 1 | AL3: =IFERROR(VLOOKUP(Matriz_Riesgos[[#This Row],[Valor del Riesgo Residual]],t_nivel_riesgo[],2,FALSE),"") -> Riesgo no significativo | AM3: Evitar | AN3: 1. Implementar controles automáticos de bloqueo ante inconsistencias de afiliación. 2. Realizar auditorías periódicas sobre autorizaciones y servicios otorgados. 3. Reforzar programas de capacitación y concientización del personal. 4. Actualizar matrices de acceso y perfiles de usuarios. 5. Establecer indicadores de monitoreo y seguimiento de incidentes LAFT asociados al proceso. 6. Implementar revisiones periódicas de calidad de datos de afiliación. | AP3: 1. Ejecutar validaciones automáticas diarias de afiliación activa. 2. Elaborar reportes mensuales de incidencias detectadas. 3. Realizar cruces de información entre afiliación, recaudación y servicios médicos. 4. Capacitar trimestralmente al personal involucrado. 5. Documentar y dar seguimiento a incidentes detectados. 6. Revisar y actualizar procedimientos operativos cada seis meses. 7. Aplicar pruebas de funcionamiento de controles tecnológicos. 8. Presentar resultados de monitoreo al comité de cumplimiento o riesgo institucional. | AX3: =IFERROR((1-Matriz_Riesgos[[#This Row],[Efectividad Total Ponderada de los Controles]])*Matriz_Riesgos[[#This Row],[Frecuencia]],"") -> 0.4 | AY3: =IFERROR((1-Matriz_Riesgos[[#This Row],[Efectividad Total Ponderada de los Controles]])*Matriz_Riesgos[[#This Row],[Impacto]],"") -> 0.4 | AZ3: =IFERROR(Matriz_Riesgos[[#This Row],[Valor del Riesgo Residual]] + 1, "") -> 2 | BA3: =IFERROR(MAX(1, ROUNDDOWN(Matriz_Riesgos[[#This Row],[Frecuencia Residual (AUX)]],0)),"") -> 1 | BB3: =IFERROR(MAX(1, ROUNDDOWN(Matriz_Riesgos[[#This Row],[Impacto Residual (AUX)]],0)),"") -> 1 | BC3: =IF(Matriz_Riesgos[[#This Row],[Frecuencia]]="","",Matriz_Riesgos[[#This Row],[Frecuencia]]) -> 4 | BD3: =IF(Matriz_Riesgos[[#This Row],[Impacto]]="","",Matriz_Riesgos[[#This Row],[Impacto]]) -> 4 | BE3: =IF(OR(Matriz_Riesgos[[#This Row],[Tope F (AUX)]]="",Matriz_Riesgos[[#This Row],[F_base (AUX)]]=""),"",MAX(0,Matriz_Riesgos[[#This Row],[Tope F (AUX)]]-Matriz_Riesgos[[#This Row],[F_base (AUX)]])) -> 3 | BF3: =IF(OR(Matriz_Riesgos[[#This Row],[Tope I (AUX)]]="",Matriz_Riesgos[[#This Row],[I_base (AUX)]]=""),"",MAX(0,Matriz_Riesgos[[#This Row],[Tope I (AUX)]]-Matriz_Riesgos[[#This Row],[I_base (AUX)]])) -> 3 | BG3: =IF(OR(Matriz_Riesgos[[#This Row],[Suma Residual redondeada (AUX)]]="",Matriz_Riesgos[[#This Row],[F_base (AUX)]]="",Matriz_Riesgos[[#This Row],[I_base (AUX)]]=""),"",MAX(0,Matriz_Riesgos[[#This Row],[Suma Residual redondeada (AUX)]]-(Matriz_Riesgos[[#This Row],[F_base (AUX)]]+Matriz_Riesgos[[#This Row],[I_base (AUX)]]))) -> 0 | BH3: =IF(OR(Matriz_Riesgos[[#This Row],[Impacto Residual (AUX)]]="",Matriz_Riesgos[[#This Row],[Frecuencia Residual (AUX)]]=""),"",IF(MOD(Matriz_Riesgos[[#This Row],[Impacto Residual (AUX)]],1) > MOD(Matriz_Riesgos[[#This Row],[Frecuencia Residual (AUX)]],1),1,IF(MOD(Matriz_Riesgos[[#This Row],[Impacto Residual (AUX)]],1) = MOD(Matriz_Riesgos[[#This Row],[Frecuencia Residual (AUX)]],1),1,0))) -> 1 | BI3: =IF(OR(Matriz_Riesgos[[#This Row],[Resto (AUX)]]="",Matriz_Riesgos[[#This Row],[Capacidad I (AUX)]]="",Matriz_Riesgos[[#This Row],[Capacidad F (AUX)]]=""),"",IF(Matriz_Riesgos[[#This Row],[Resto (AUX)]]=0, 0,IF(Matriz_Riesgos[[#This Row],[Resto (AUX)]]=1,MIN(Matriz_Riesgos[[#This Row],[Capacidad I (AUX)]], IF(OR(Matriz_Riesgos[[#This Row],[Prefiere I (AUX)]]=1,Matriz_Riesgos[[#This Row],[Capacidad F (AUX)]]=0),1,0)),MIN(Matriz_Riesgos[[#This Row],[Capacidad I (AUX)]],IF(Matriz_Riesgos[[#This Row],[Prefiere I (AUX)]]=1,1 + IF(Matriz_Riesgos[[#This Row],[Capacidad F (AUX)]]>0,0,1),IF(Matriz_Riesgos[[#This Row],[Capacidad F (AUX)]]>0,1,2)))))) -> 0 | BJ3: =IF(OR(Matriz_Riesgos[[#This Row],[Resto (AUX)]]="",Matriz_Riesgos[[#This Row],[Capacidad F (AUX)]]="",Matriz_Riesgos[[#This Row],[Inc_I (AUX)]]=""),"",MIN(Matriz_Riesgos[[#This Row],[Capacidad F (AUX)]], MAX(0,Matriz_Riesgos[[#This Row],[Resto (AUX)]]-Matriz_Riesgos[[#This Row],[Inc_I (AUX)]]))) -> 0 | BK3: =IFERROR(MAX(ROUND(Matriz_Riesgos[[#This Row],[Frecuencia Residual (AUX)]]+Matriz_Riesgos[[#This Row],[Impacto Residual (AUX)]]-1+Matriz_Riesgos[[#This Row],[Efectividad Total Ponderada de los Controles]],0),1),"") -> 1 | BL3: =IFERROR(Matriz_Riesgos[[#This Row],[Valor del Riesgo Residual]]-Matriz_Riesgos[[#This Row],[Valor del Riesgo Residual (AUX)]],"") -> 0 | BM3: =IFERROR(Matriz_Riesgos[[#This Row],[Frecuencia Residual]]+Matriz_Riesgos[[#This Row],[Impacto Residual]]-1,"") -> 1 | BN3: =IFERROR(Matriz_Riesgos[[#This Row],[Valor del Riesgo Residual]]-Matriz_Riesgos[[#This Row],[VRR 2]],"") -> 0 | BO3: =IFERROR(Matriz_Riesgos[[#This Row],[Frecuencia]]-Matriz_Riesgos[[#This Row],[Frecuencia Residual]],"") -> 3 | BP3: =IFERROR(Matriz_Riesgos[[#This Row],[Impacto]]-Matriz_Riesgos[[#This Row],[Impacto Residual]],"") -> 3 | BQ3: =IFERROR(Matriz_Riesgos[[#This Row],[Valor del Riesgo Inherente]]-Matriz_Riesgos[[#This Row],[Valor del Riesgo Residual]],"") -> 6 | BR3: 1. Emisión recurrente de autorizaciones manuales o fuera del flujo normal. 2. Prestación de servicios a personas con afiliación suspendida, inexistente o inconsistente. 3. Incremento inusual de anulaciones o correcciones de autorizaciones. 4. Usuarios internos que realizan modificaciones frecuentes en registros de afiliación. 5. Diferencias entre la base de afiliados activos y los servicios facturados. 6. Reclamos o denuncias relacionados con uso indebido de cobertura médica. 7. Accesos al sistema fuera de horarios habituales o desde ubicaciones no autorizadas. 8. Uso reiterado de credenciales por distintos usuarios.
A4: 3 | B4: ROTR-PENS-3 | C4: Pensiones | E4: Otros Riesgos | F4: Reconocimiento de Pensiones | H4: Aprobación y reconocimiento de una prestación pensional a una persona que no cumple los requisitos legales | I4: Descripción: Posibilidad de que el IHSS reconozca y otorgue una pensión con base en información falsa, adulterada o incompleta respecto a semanas cotizadas, historia laboral, edad, estado civil, invalidez u otros requisitos legales, debido a deficiencias en los procesos de validación y verificación documental Causas: Procesos manuales sin doble revisión técnica, colusión entre funcionarios y solicitantes, falsificación documental no detectada. Efecto: Alto impacto financiero y reputacional, procesos disciplinarios contra funcionarios | J4: 3 | K4: 5 | L4: =IF((Matriz_Riesgos[[#This Row],[Frecuencia]]+Matriz_Riesgos[[#This Row],[Impacto]]-1)=-1,"",Matriz_Riesgos[[#This Row],[Frecuencia]]+Matriz_Riesgos[[#This Row],[Impacto]]-1) -> 7 | M4: =IFERROR(VLOOKUP(Matriz_Riesgos[[#This Row],[Valor del Riesgo Inherente]],t_nivel_riesgo[],2,FALSE), "") -> Riesgo Alto | N4: Pensiones | O4: IVM | P4: Fraude, LAFT, incumplimiento regulatorio. Riesgo operativo, Riesgo reputacional, corrupcion, tecnologico | T4: 1. Validación biométrica del solicitante 2. Implementación de controles de acceso y trazabilidad sobre expedientes físicos y electrónicos. 3. Verificación de autenticidad de documentos mediante consultas a registros oficiales, bases de datos institucionales y fuentes independientes. 4. Aplicación de procesos de debida diligencia para verificar la identidad del solicitante, beneficiarios y apoderados, cuando corresponda. 5. Segregación de funciones entre las áreas responsables de recepción, análisis, validación, recomendación y aprobación de prestaciones. 6. Capacitación periódica al personal sobre prevención de fraude, corrupción, LAFT y detección de documentación falsa o alterada. 7. | U4: Inexistente | V4: =IFERROR(VLOOKUP(U4,Listas!$A$30:$C$35,2,FALSE),"") | W4: =IFERROR(VLOOKUP(U4,Listas!$A$30:$C$35,3,FALSE),"") | X4: 1. Indicador de pensiones revocadas (cuántas pensiones que ya habían sido reconocidas, posteriormente fueron anuladas, revocadas o dejadas sin efecto por detectar inconsistencias, errores o fraude). 2.- Análisis de patrones inusuales en reconocimientos 3. Revisiones de calidad y validaciones independientes sobre expedientes previamente aprobados. 4. Auditorías periódicas de expedientes pensionales y beneficios otorgados. 5. Generación de reportes de alertas sobre modificaciones posteriores a la aprobación de beneficios. 6. Revisiones aleatorias de expedientes por parte de las áreas de control interno, cumplimiento o auditoría 7. Monitoreo de usuarios con accesos privilegiados o intervenciones inusuales sobre expedientes de prestaciones. | Y4: Inexistente | Z4: =IFERROR(VLOOKUP(Y4,Listas!$A$30:$C$35,2,FALSE),"") | AA4: =IFERROR(VLOOKUP(Y4,Listas!$A$30:$C$35,3,FALSE),"") | AB4: 1.- Suspensión preventiva del trámite o del beneficio cuando se identifiquen inconsistencias relevantes o indicios de fraude. 2. Recuperación de pagos efectuados indebidamente conforme al marco legal aplicable. 3. Aplicación de medidas disciplinarias cuando se determine participación o negligencia de funcionarios. 4. Fortalecimiento de controles y procedimientos asociados al hallazgo identificado. 5. Comunicación y reporte a las autoridades competentes cuando existan indicios de fraude, corrupción, falsificación documental, lavado de activos u otros ilícitos. | AC4: Inexistente | AD4: =IFERROR(VLOOKUP(AC4,Listas!$A$30:$C$35,2,FALSE),"") | AE4: =IFERROR(VLOOKUP(AC4,Listas!$A$30:$C$35,3,FALSE),"") | AG4: =IF(AND(T4="",X4="",AB4=""),"",('Otras Tablas'!$B$3*IF(W4="",0,W4)+'Otras Tablas'!$B$4*IF(AA4="",0,AA4)+'Otras Tablas'!$B$5*IF(AE4="",0,AE4))) | AH4: =IF(Matriz_Riesgos[[#This Row],[Riesgo Inherente]]="","",Matriz_Riesgos[[#This Row],[Riesgo Inherente]]) -> Aprobación y reconocimiento de una prestación pensional a una persona que no cumple los requisitos legales | AI4: =IFERROR(IF(OR(Matriz_Riesgos[[#This Row],[Frecuencia]]="",Matriz_Riesgos[[#This Row],[Impacto]]="",Matriz_Riesgos[[#This Row],[Valor del Riesgo Inherente]]="",Matriz_Riesgos[[#This Row],[Valor del Riesgo Residual]]=""),"",IF(Matriz_Riesgos[[#This Row],[Valor del Riesgo Inherente]]=Matriz_Riesgos[[#This Row],[Valor del Riesgo Residual]],Matriz_Riesgos[[#This Row],[Frecuencia]],MIN(Matriz_Riesgos[[#This Row],[Tope F (AUX)]], Matriz_Riesgos[[#This Row],[F_base (AUX)]]+Matriz_Riesgos[[#This Row],[Inc_F (AUX)]]))),"") | AJ4: =IFERROR(IF(OR(Matriz_Riesgos[[#This Row],[Frecuencia]]="",Matriz_Riesgos[[#This Row],[Impacto]]="",Matriz_Riesgos[[#This Row],[Valor del Riesgo Inherente]]="",Matriz_Riesgos[[#This Row],[Valor del Riesgo Residual]]=""),"",IF(Matriz_Riesgos[[#This Row],[Valor del Riesgo Inherente]]=Matriz_Riesgos[[#This Row],[Valor del Riesgo Residual]],Matriz_Riesgos[[#This Row],[Impacto]],MIN(Matriz_Riesgos[[#This Row],[Tope I (AUX)]], Matriz_Riesgos[[#This Row],[I_base (AUX)]]+Matriz_Riesgos[[#This Row],[Inc_I (AUX)]]))),"") | AK4: =IFERROR(ROUND(MAX(1,Matriz_Riesgos[[#This Row],[Valor del Riesgo Inherente]]*(1 - Matriz_Riesgos[[#This Row],[Efectividad Total Ponderada de los Controles]])),0), "") | AL4: =IFERROR(VLOOKUP(Matriz_Riesgos[[#This Row],[Valor del Riesgo Residual]],t_nivel_riesgo[],2,FALSE),"") | AM4: Evitar | AN4: 1. Revisar y fortalecer los procedimientos de evaluación y aprobación de prestaciones. 2. Incrementar la frecuencia de auditorías sobre expedientes de alto riesgo. 3. Establecer mecanismos de doble revisión para casos complejos o excepcionales. 4. Actualizar periódicamente los criterios de segmentación y perfiles de riesgo. 5. Desarrollar programas continuos de capacitación y concienciación para el personal involucrado. 6. Implementar indicadores de gestión y alertas tempranas para identificar desviaciones en los procesos de aprobación. | AO4: 6 | AP4: 1. Verificación documental y legal de requisitos 2. Validación de identidad y autenticidad documental 3. Consulta en listas restrictivas y PEP 4. Revisión independiente de expedientes seleccionados 5. Auditoría de prestaciones aprobadas 6. Capacitación en fraude, LAFT y control interno 7. Actualización de procedimientos y controles 8. Seguimiento de hallazgos y planes de acción | AQ4: 8 | AX4: =IFERROR((1-Matriz_Riesgos[[#This Row],[Efectividad Total Ponderada de los Controles]])*Matriz_Riesgos[[#This Row],[Frecuencia]],"") | AY4: =IFERROR((1-Matriz_Riesgos[[#This Row],[Efectividad Total Ponderada de los Controles]])*Matriz_Riesgos[[#This Row],[Impacto]],"") | AZ4: =IFERROR(Matriz_Riesgos[[#This Row],[Valor del Riesgo Residual]] + 1, "") | BA4: =IFERROR(MAX(1, ROUNDDOWN(Matriz_Riesgos[[#This Row],[Frecuencia Residual (AUX)]],0)),"") | BB4: =IFERROR(MAX(1, ROUNDDOWN(Matriz_Riesgos[[#This Row],[Impacto Residual (AUX)]],0)),"") | BC4: =IF(Matriz_Riesgos[[#This Row],[Frecuencia]]="","",Matriz_Riesgos[[#This Row],[Frecuencia]]) -> 3 | BD4: =IF(Matriz_Riesgos[[#This Row],[Impacto]]="","",Matriz_Riesgos[[#This Row],[Impacto]]) -> 5 | BE4: =IF(OR(Matriz_Riesgos[[#This Row],[Tope F (AUX)]]="",Matriz_Riesgos[[#This Row],[F_base (AUX)]]=""),"",MAX(0,Matriz_Riesgos[[#This Row],[Tope F (AUX)]]-Matriz_Riesgos[[#This Row],[F_base (AUX)]])) | BF4: =IF(OR(Matriz_Riesgos[[#This Row],[Tope I (AUX)]]="",Matriz_Riesgos[[#This Row],[I_base (AUX)]]=""),"",MAX(0,Matriz_Riesgos[[#This Row],[Tope I (AUX)]]-Matriz_Riesgos[[#This Row],[I_base (AUX)]])) | BG4: =IF(OR(Matriz_Riesgos[[#This Row],[Suma Residual redondeada (AUX)]]="",Matriz_Riesgos[[#This Row],[F_base (AUX)]]="",Matriz_Riesgos[[#This Row],[I_base (AUX)]]=""),"",MAX(0,Matriz_Riesgos[[#This Row],[Suma Residual redondeada (AUX)]]-(Matriz_Riesgos[[#This Row],[F_base (AUX)]]+Matriz_Riesgos[[#This Row],[I_base (AUX)]]))) | BH4: =IF(OR(Matriz_Riesgos[[#This Row],[Impacto Residual (AUX)]]="",Matriz_Riesgos[[#This Row],[Frecuencia Residual (AUX)]]=""),"",IF(MOD(Matriz_Riesgos[[#This Row],[Impacto Residual (AUX)]],1) > MOD(Matriz_Riesgos[[#This Row],[Frecuencia Residual (AUX)]],1),1,IF(MOD(Matriz_Riesgos[[#This Row],[Impacto Residual (AUX)]],1) = MOD(Matriz_Riesgos[[#This Row],[Frecuencia Residual (AUX)]],1),1,0))) | BI4: =IF(OR(Matriz_Riesgos[[#This Row],[Resto (AUX)]]="",Matriz_Riesgos[[#This Row],[Capacidad I (AUX)]]="",Matriz_Riesgos[[#This Row],[Capacidad F (AUX)]]=""),"",IF(Matriz_Riesgos[[#This Row],[Resto (AUX)]]=0, 0,IF(Matriz_Riesgos[[#This Row],[Resto (AUX)]]=1,MIN(Matriz_Riesgos[[#This Row],[Capacidad I (AUX)]], IF(OR(Matriz_Riesgos[[#This Row],[Prefiere I (AUX)]]=1,Matriz_Riesgos[[#This Row],[Capacidad F (AUX)]]=0),1,0)),MIN(Matriz_Riesgos[[#This Row],[Capacidad I (AUX)]],IF(Matriz_Riesgos[[#This Row],[Prefiere I (AUX)]]=1,1 + IF(Matriz_Riesgos[[#This Row],[Capacidad F (AUX)]]>0,0,1),IF(Matriz_Riesgos[[#This Row],[Capacidad F (AUX)]]>0,1,2)))))) | BJ4: =IF(OR(Matriz_Riesgos[[#This Row],[Resto (AUX)]]="",Matriz_Riesgos[[#This Row],[Capacidad F (AUX)]]="",Matriz_Riesgos[[#This Row],[Inc_I (AUX)]]=""),"",MIN(Matriz_Riesgos[[#This Row],[Capacidad F (AUX)]], MAX(0,Matriz_Riesgos[[#This Row],[Resto (AUX)]]-Matriz_Riesgos[[#This Row],[Inc_I (AUX)]]))) | BK4: =IFERROR(MAX(ROUND(Matriz_Riesgos[[#This Row],[Frecuencia Residual (AUX)]]+Matriz_Riesgos[[#This Row],[Impacto Residual (AUX)]]-1+Matriz_Riesgos[[#This Row],[Efectividad Total Ponderada de los Controles]],0),1),"") | BL4: =IFERROR(Matriz_Riesgos[[#This Row],[Valor del Riesgo Residual]]-Matriz_Riesgos[[#This Row],[Valor del Riesgo Residual (AUX)]],"") | BM4: =IFERROR(Matriz_Riesgos[[#This Row],[Frecuencia Residual]]+Matriz_Riesgos[[#This Row],[Impacto Residual]]-1,"") | BN4: =IFERROR(Matriz_Riesgos[[#This Row],[Valor del Riesgo Residual]]-Matriz_Riesgos[[#This Row],[VRR 2]],"") | BO4: =IFERROR(Matriz_Riesgos[[#This Row],[Frecuencia]]-Matriz_Riesgos[[#This Row],[Frecuencia Residual]],"") | BP4: =IFERROR(Matriz_Riesgos[[#This Row],[Impacto]]-Matriz_Riesgos[[#This Row],[Impacto Residual]],"") | BQ4: =IFERROR(Matriz_Riesgos[[#This Row],[Valor del Riesgo Inherente]]-Matriz_Riesgos[[#This Row],[Valor del Riesgo Residual]],"") | BR4: 1. Expedientes con documentación incompleta, inconsistente o alterada. 2. Incremento inusual de solicitudes provenientes de una misma fuente o gestor. 3. Modificaciones frecuentes de datos personales antes de la aprobación. 4. Presión indebida para acelerar procesos o evitar controles establecidos. 5. Coincidencias con listas restrictivas, sancionatorias o registros de investigación. 6. Falta de soporte documental suficiente para acreditar el derecho a la prestación. 7. Pagos o beneficios aprobados bajo esquemas de excepción sin la debida justificación y autorización.
A5: 4 | B5: ROTR-PENS-4 | C5: Pensiones | E5: Otros Riesgos | F5: Pago de Pensiones | H5: Pago de una o más cuotas de pension, posteriores a la fecha real de fallecimiento del pensionado, sin que el sistema del IHSS haya bloqueado oportunamente el beneficio | I5: Descripción: Posibilidad de que la entidad continúe efectuando el pago de mesadas pensionales después del fallecimiento del beneficiario, debido a fallas en la actualización de información vital, ausencia de cruces con bases oficiales o deficiencias en los controles de verificación periódica. Causas: No existe un proceso de cruce de base de datos del IHSS contra la del RNP (Defunciones), Retraso, por parte de los familiares, en el reporte del fallecimiento del pensionado, Debilidad en el proceso de supervivencia Cobro fraudulento por terceros (familiares o apoderados) Efecto: Perdida financiera, riesgo reputacional (mal manejo de fondos publicos) | J5: 3 | K5: 5 | L5: =IF((Matriz_Riesgos[[#This Row],[Frecuencia]]+Matriz_Riesgos[[#This Row],[Impacto]]-1)=-1,"",Matriz_Riesgos[[#This Row],[Frecuencia]]+Matriz_Riesgos[[#This Row],[Impacto]]-1) -> 7 | M5: =IFERROR(VLOOKUP(Matriz_Riesgos[[#This Row],[Valor del Riesgo Inherente]],t_nivel_riesgo[],2,FALSE), "") -> Riesgo Alto | N5: Pensiones | O5: IVM | P5: Fraude, LAFT, incumplimiento regulatorio. Riesgo operativo, Riesgo reputacional | T5: 1. Cruce automático y periódico con base de datos del RNP (defunciones) 2. Proceso de sobrevivencia digital (Huella) | X5: 1. Indicador de pagos posteriores a fecha de fallecimiento (detectadas / total pensiones x100). 2. Auditorías periódicas a pensionados de mayor edad 3. Reportes de inconsistencias bancarias (Planillas dejadas de cobrar) | AB5: 1.- Suspension de pago 2. Denuncia penal | AG5: =IF(AND(T5="",X5="",AB5=""),"",('Otras Tablas'!$B$3*IF(W5="",0,W5)+'Otras Tablas'!$B$4*IF(AA5="",0,AA5)+'Otras Tablas'!$B$5*IF(AE5="",0,AE5))) | AH5: =IF(Matriz_Riesgos[[#This Row],[Riesgo Inherente]]="","",Matriz_Riesgos[[#This Row],[Riesgo Inherente]]) -> Pago de una o más cuotas de pension, posteriores a la fecha real de fallecimiento del pensionado, sin que el sistema del IHSS haya bloqueado oportunamente el beneficio | AI5: =IFERROR(IF(OR(Matriz_Riesgos[[#This Row],[Frecuencia]]="",Matriz_Riesgos[[#This Row],[Impacto]]="",Matriz_Riesgos[[#This Row],[Valor del Riesgo Inherente]]="",Matriz_Riesgos[[#This Row],[Valor del Riesgo Residual]]=""),"",IF(Matriz_Riesgos[[#This Row],[Valor del Riesgo Inherente]]=Matriz_Riesgos[[#This Row],[Valor del Riesgo Residual]],Matriz_Riesgos[[#This Row],[Frecuencia]],MIN(Matriz_Riesgos[[#This Row],[Tope F (AUX)]], Matriz_Riesgos[[#This Row],[F_base (AUX)]]+Matriz_Riesgos[[#This Row],[Inc_F (AUX)]]))),"") -> 3 | AJ5: =IFERROR(IF(OR(Matriz_Riesgos[[#This Row],[Frecuencia]]="",Matriz_Riesgos[[#This Row],[Impacto]]="",Matriz_Riesgos[[#This Row],[Valor del Riesgo Inherente]]="",Matriz_Riesgos[[#This Row],[Valor del Riesgo Residual]]=""),"",IF(Matriz_Riesgos[[#This Row],[Valor del Riesgo Inherente]]=Matriz_Riesgos[[#This Row],[Valor del Riesgo Residual]],Matriz_Riesgos[[#This Row],[Impacto]],MIN(Matriz_Riesgos[[#This Row],[Tope I (AUX)]], Matriz_Riesgos[[#This Row],[I_base (AUX)]]+Matriz_Riesgos[[#This Row],[Inc_I (AUX)]]))),"") -> 5 | AK5: =IFERROR(ROUND(MAX(1,Matriz_Riesgos[[#This Row],[Valor del Riesgo Inherente]]*(1 - Matriz_Riesgos[[#This Row],[Efectividad Total Ponderada de los Controles]])),0), "") -> 7 | AL5: =IFERROR(VLOOKUP(Matriz_Riesgos[[#This Row],[Valor del Riesgo Residual]],t_nivel_riesgo[],2,FALSE),"") -> Riesgo Alto | AM5: Evitar | AX5: =IFERROR((1-Matriz_Riesgos[[#This Row],[Efectividad Total Ponderada de los Controles]])*Matriz_Riesgos[[#This Row],[Frecuencia]],"") -> 3 | AY5: =IFERROR((1-Matriz_Riesgos[[#This Row],[Efectividad Total Ponderada de los Controles]])*Matriz_Riesgos[[#This Row],[Impacto]],"") -> 5 | AZ5: =IFERROR(Matriz_Riesgos[[#This Row],[Valor del Riesgo Residual]] + 1, "") -> 8 | BA5: =IFERROR(MAX(1, ROUNDDOWN(Matriz_Riesgos[[#This Row],[Frecuencia Residual (AUX)]],0)),"") -> 3 | BB5: =IFERROR(MAX(1, ROUNDDOWN(Matriz_Riesgos[[#This Row],[Impacto Residual (AUX)]],0)),"") -> 5 | BC5: =IF(Matriz_Riesgos[[#This Row],[Frecuencia]]="","",Matriz_Riesgos[[#This Row],[Frecuencia]]) -> 3 | BD5: =IF(Matriz_Riesgos[[#This Row],[Impacto]]="","",Matriz_Riesgos[[#This Row],[Impacto]]) -> 5 | BE5: =IF(OR(Matriz_Riesgos[[#This Row],[Tope F (AUX)]]="",Matriz_Riesgos[[#This Row],[F_base (AUX)]]=""),"",MAX(0,Matriz_Riesgos[[#This Row],[Tope F (AUX)]]-Matriz_Riesgos[[#This Row],[F_base (AUX)]])) -> 0 | BF5: =IF(OR(Matriz_Riesgos[[#This Row],[Tope I (AUX)]]="",Matriz_Riesgos[[#This Row],[I_base (AUX)]]=""),"",MAX(0,Matriz_Riesgos[[#This Row],[Tope I (AUX)]]-Matriz_Riesgos[[#This Row],[I_base (AUX)]])) -> 0 | BG5: =IF(OR(Matriz_Riesgos[[#This Row],[Suma Residual redondeada (AUX)]]="",Matriz_Riesgos[[#This Row],[F_base (AUX)]]="",Matriz_Riesgos[[#This Row],[I_base (AUX)]]=""),"",MAX(0,Matriz_Riesgos[[#This Row],[Suma Residual redondeada (AUX)]]-(Matriz_Riesgos[[#This Row],[F_base (AUX)]]+Matriz_Riesgos[[#This Row],[I_base (AUX)]]))) -> 0 | BH5: =IF(OR(Matriz_Riesgos[[#This Row],[Impacto Residual (AUX)]]="",Matriz_Riesgos[[#This Row],[Frecuencia Residual (AUX)]]=""),"",IF(MOD(Matriz_Riesgos[[#This Row],[Impacto Residual (AUX)]],1) > MOD(Matriz_Riesgos[[#This Row],[Frecuencia Residual (AUX)]],1),1,IF(MOD(Matriz_Riesgos[[#This Row],[Impacto Residual (AUX)]],1) = MOD(Matriz_Riesgos[[#This Row],[Frecuencia Residual (AUX)]],1),1,0))) -> 1 | BI5: =IF(OR(Matriz_Riesgos[[#This Row],[Resto (AUX)]]="",Matriz_Riesgos[[#This Row],[Capacidad I (AUX)]]="",Matriz_Riesgos[[#This Row],[Capacidad F (AUX)]]=""),"",IF(Matriz_Riesgos[[#This Row],[Resto (AUX)]]=0, 0,IF(Matriz_Riesgos[[#This Row],[Resto (AUX)]]=1,MIN(Matriz_Riesgos[[#This Row],[Capacidad I (AUX)]], IF(OR(Matriz_Riesgos[[#This Row],[Prefiere I (AUX)]]=1,Matriz_Riesgos[[#This Row],[Capacidad F (AUX)]]=0),1,0)),MIN(Matriz_Riesgos[[#This Row],[Capacidad I (AUX)]],IF(Matriz_Riesgos[[#This Row],[Prefiere I (AUX)]]=1,1 + IF(Matriz_Riesgos[[#This Row],[Capacidad F (AUX)]]>0,0,1),IF(Matriz_Riesgos[[#This Row],[Capacidad F (AUX)]]>0,1,2)))))) -> 0 | BJ5: =IF(OR(Matriz_Riesgos[[#This Row],[Resto (AUX)]]="",Matriz_Riesgos[[#This Row],[Capacidad F (AUX)]]="",Matriz_Riesgos[[#This Row],[Inc_I (AUX)]]=""),"",MIN(Matriz_Riesgos[[#This Row],[Capacidad F (AUX)]], MAX(0,Matriz_Riesgos[[#This Row],[Resto (AUX)]]-Matriz_Riesgos[[#This Row],[Inc_I (AUX)]]))) -> 0 | BK5: =IFERROR(MAX(ROUND(Matriz_Riesgos[[#This Row],[Frecuencia Residual (AUX)]]+Matriz_Riesgos[[#This Row],[Impacto Residual (AUX)]]-1+Matriz_Riesgos[[#This Row],[Efectividad Total Ponderada de los Controles]],0),1),"") -> 7 | BL5: =IFERROR(Matriz_Riesgos[[#This Row],[Valor del Riesgo Residual]]-Matriz_Riesgos[[#This Row],[Valor del Riesgo Residual (AUX)]],"") -> 0 | BM5: =IFERROR(Matriz_Riesgos[[#This Row],[Frecuencia Residual]]+Matriz_Riesgos[[#This Row],[Impacto Residual]]-1,"") -> 7 | BN5: =IFERROR(Matriz_Riesgos[[#This Row],[Valor del Riesgo Residual]]-Matriz_Riesgos[[#This Row],[VRR 2]],"") -> 0 | BO5: =IFERROR(Matriz_Riesgos[[#This Row],[Frecuencia]]-Matriz_Riesgos[[#This Row],[Frecuencia Residual]],"") -> 0 | BP5: =IFERROR(Matriz_Riesgos[[#This Row],[Impacto]]-Matriz_Riesgos[[#This Row],[Impacto Residual]],"") -> 0 | BQ5: =IFERROR(Matriz_Riesgos[[#This Row],[Valor del Riesgo Inherente]]-Matriz_Riesgos[[#This Row],[Valor del Riesgo Residual]],"") -> 0
